Workbook

Sheet Index
A1: Monkey-Myth Matrix — Index & Reconciliation Map
A2: Spine (essays) <-> Matrix (rows) crosswalk · what's built vs. what the essays promise · what's owed next
A3: Reference map, updated 2026-08-18. Cluster + tier counts are live formulas. Now 84 rows / 18 active codes: 17 evidence clusters plus the AD-01 methodology lens. v0.21 adds an explicit evidence/adaptation boundary.
A5: 1 · The three layers
A6: Layer | B6: Source document(s) | D6: Holds
A7: Doctrine | B7: Handoff Packet | D7: Guardrails; confidence tiers (1 / 2 / 3); model failure-mode list; build steps; keeper lines. The operating manual.
A8: Spine | B8: MFM + Priesthood-Function (both CC0) | D8: Foundational lens; the bulk of Tier 1-2 readings; the Tier-3 speculative branches; the mechanism vocabulary. Richer than the matrix.
A9: Matrix | B9: This workbook (12 data/scaffold sheets) | D9: 84 rows across 17 evidence clusters + AD-01 methodology lens; 18 sheets including Story Bridge, source queues, prompts, validation, and change logs.
A11: 2 · Spine -> Matrix crosswalk (every essay section, where it lives, what's owed)
A12: Spine ref | B12: Covers | C12: Tier | D12: Cluster(s) | E12: Rows present | F12: Status / what's owed
A13: MFM §1-3, 3A | B13: Thesis; monkey-politics lens; myth as processed memory; drift mechanics | C13: 1-2 | D13: lens / method | E13: — | F13: Doctrine & method, not rows.
A14: MFM §4 | B14: Labor revolt: Atrahasis (Igigi revolt -> human worker) | C14: 1 | D14: FM-01, RF-01, TR-01 | E14: FM-001, TR-001 | F14: Atrahasis sits in as a FLOOD row; the labor-revolt angle has no dedicated row. OWED.
A15: MFM §5 | B15: Watchers / Nephilim / hybrid anxiety | C15: 2 | D15: RF-01 | E15: RF-003 | F15: Built.
A16: MFM §5A | B16: The smith & technology taboo | C16: 2 | D16: RF-01 | E16: RF-002, RF-003, RF-006, RF-007, RF-008 | F16: BUILT - Hephaestus + Wayland (captured-maker pole), Tubal-Cain (technology-taboo pole) added this pass
A17: MFM §6 | B17: Succession: gods as ruling houses | C17: 1-2 | D17: SC-01, OO-01 | E17: SC-001/002/003 | F17: OWED: divine-succession cycle (Uranus/Cronus/Zeus, Kumarbi).
A18: MFM §6A | B18: Sacred geography: property law with incense | C18: 2 | D18: SG-01 | E18: SG-001 | F18: Thinnest cluster (1 row). OWED: more land-claim rows.
A19: MFM §6B | B19: Scapegoat engine (Girard, contested) | C19: 2 | D19: SC-01 | E19: (mechanism behind SC) | F19: The motor under SC-01. Caveat: mimetic theory is literary, not primatology.
A20: MFM §7 | B20: Narrative heist: Atrahasis -> Marduk | C20: 1-2 | D20: PB-01, OO-01 | E20: PB-001, OO-001 | F20: Core anchor. Built & strong.
A21: MFM §7A | B21: Covenant as vassal treaty (Hittite -> biblical) | C21: 1-2 | D21: CC-01 | E21: CC-001 | F21: DONE — founding row of CC-01. Tier 1 (form) / Tier 2 (capture-reading & dating).
A22: MFM §8 | B22: The feminine under capture (demonize / split) | C22: 2 | D22: DF-01 | E22: DF-001..005 | F22: Built — now the DEMONIZED/split figures only (Tiamat, Lamashtu, Lilith, Medusa, Coyolxauhqui). Co-opted ones moved to UF-01.
A23: MFM §9 | B23: Inanna/Ishtar/Kali — 'furnace with a face' | C23: 1-2 | D23: UF-01 | E23: UF-001 - UF-006 | F23: DONE - UF-01 now holds 6: Inanna, Kali, Athena, Durga, Sekhmet, Cybele across all 3 sub-types
... A36: PF Counter. | B36: Distributed authority; refusal of closure; non-divisible org; relational/assembler | C36: 1 | D36: anti-capture doctrine | E36: — | F36: Doctrine. The 12-vs-remainder lens is what the date-log numerology violated.
A38: 3 · Rows & clusters still owed (the 'continue forward' menu)
A39: Item | B39: What / where | C39: Tier | D39: Target | E39: From | F39: Priority / note
A40: Covenant / vassal-treaty | B40: Hittite -> biblical covenant as capture | C40: 1-2 | D40: CC-01 (new) | E40: MFM §7A | F40: DONE — CC-001, founding row of CC-01.
A41: Inanna / Ishtar row | B41: The unsplit / co-opted feminine | C41: 1-2 | D41: UF-01 (new) | E41: MFM §9 | F41: DONE — UF-001; DF-01 split into demonized (DF-01) vs co-opted/uncontained (UF-01).
A42: Captured-craftsman rows | B42: Hephaestus, Wayland, Tubal-Cain | C42: 2 | D42: RF-01 | E42: MFM §5A | F42: DONE - RF-006 Hephaestus (crippled-maker), RF-007 Wayland (enslaved-maker), RF-008 Tubal-Cain (marked-lineage); §5A sub-cluster complete
A43: Resurrection-as-refusal | B43: Refusal of administrative closure | C43: 1 | D43: DT-01 | E43: PF Case 3 | F43: DONE - DT-003 Osiris / DT-004 Dumuzi / DT-005 Baal added across 3 sub-types; PF Case 3 now represented
A44: Atrahasis labor row | B44: Revolt -> replacement labor (distinct from flood) | C44: 1 | D44: RF-01 / FM-01 | E44: MFM §4 | F44: MED
A45: Divine-succession cycle | B45: Uranus/Cronus/Zeus; Kumarbi | C45: 1-2 | D45: OO-01 / SC-01 | E45: MFM §6 | F45: MED
A46: Populate UF-01 | B46: Athena (co-opted), Durga, Sekhmet, Cybele | C46: 1-2 | D46: UF-01 | E46: MFM §9 | F46: LARGELY DONE - Athena, Durga (constituted), Sekhmet (uncontained), Cybele (harnessed) added this pass; UF-01 = 6 figures
A47: Sibling rows for CC-01 | B47: Debt-bondage / jubilee; Esarhaddon oath; tamitu | C47: 1-2 | D47: CC-01 | E47: PF §4 | F47: DONE - CC-002 debt-bondage/Jubilee (debt-release), CC-003 Esarhaddon ade (loyalty-oath), CC-004 tamitu (oracular-access) added; CC-01 now 4, sub-type tagged
A48: Expand sacred geography | B48: More land-claim rows | C48: 2 | D48: SG-01 | E48: MFM §6A | F48: LOW-MED — thinnest cluster
A49: Pharisees entry | B49: Distributed remainder after a center falls | C49: 1 | D49: systems | E49: PF Case 2 | F49: DONE - built as DR-01 (new cluster): Pharisees/rabbinic Judaism (DR-001) + Reformation + Buddha
A50: CREATE CT-01 | B50: Celestial / Climate Trauma Signal | C50: 2-3 | D50: new cluster | E50: Handoff | F50: Quarantine; holds the Göbekli pass once done
... A53: CREATE Tier-3 bins | B53: Monster taxonomy (MT-01), cousin-monkey, body-paint | C53: 3 | D53: new cluster(s) | E53: MFM §10A/13/14 | F53: Labeled Tier-3 bins so they can't leak into the Tier 1-2 matrix
A55: 4 · Cluster roster (v0.21 builds 18 active codes: 17 evidence clusters + AD-01 method lens; counts are live)
A56: Code | B56: Name | C56: Status | D56: Rows (live) | E56: Tier home | F56: Note
A57: PB-01 | B57: Primordial Body / Corpse-World | C57: Built | D57: =COUNTIF('Master Matrix'!$B:$B,"PB-01") -> 5 | E57: 1-2 mostly
A58: OO-01 | B58: Ordering Operator / New Boss | C58: Built | D58: =COUNTIF('Master Matrix'!$B:$B,"OO-01") -> 5 | E58: 1-2 mostly
...

Sheet Dashboard
A1: Comparative Monkey-Myth Matrix
A2: Purpose | B2: Track recurring mythic functions as hominid/social systems patterns, while keeping confidence tiers and source status visible.
A3: Guardrail | B3: Not one secret origin story. Compare functions, power mechanics, narrative capture, and remainder. No crown; no mandatory interpreter.
A4: Source spine | B4: Myth as Fossilized Monkey Politics + Priesthood-Function. Treat this as a working matrix to patch, fork, and source-pass.
A5: Created | B5: Updated 2026-08-18 · v0.21
J6: FRAME TEST — can a row fail? | N6: EVIDENCE / ADAPTATION BOUNDARY
A7: Cluster ID | B7: Cluster Name | C7: Starter Rows | D7: Notes | F7: Confidence Tier | G7: Rows | H7: Meaning | J7: Fit Verdict | K7: Rows | N7: Evidence Mode | O7: Rows
A8: PB-01 | B8: Primordial Body / Corpse-World | C8: =COUNTIF('Master Matrix'!$B:$B,A8) -> 5 | D8: Prior living/generative body killed, sacrificed, or disassembled into world/infrastructure. | F8: Tier 1 | G8: =COUNTIF('Master Matrix'!$L:$L,"Tier 1") -> 3 | H8: Grounded textual/social structure or internal framework. | J8: Fits | K8: =COUNTIF('Master Matrix'!$AC:$AC,"Fits") -> 13 | N8: Ancient textual core | O8: =COUNTIF('Master Matrix'!$AE:$AE,N8) -> 15
A9: OO-01 | B9: Ordering Operator / New Boss | C9: =COUNTIF('Master Matrix'!$B:$B,A9) -> 5 | D9: Violent or strategic organizer converts crisis into permanent sovereignty. | F9: Tier 1-2 | G9: =COUNTIF('Master Matrix'!$L:$L,"Tier 1-2") -> 67 | H9: Strong motif with plausible interpretive layer. | J9: Partial fit | K9: =COUNTIF('Master Matrix'!$AC:$AC,"Partial fit") -> 13 | N9: Ancient variant / reception | O9: =COUNTIF('Master Matrix'!$AE:$AE,N9) -> 1
A10: RF-01 | B10: Rebel Blood / Embedded Remainder | C10: =COUNTIF('Master Matrix'!$B:$B,A10) -> 8 | D10: Refusal, rebel material, or unauthorized knowledge becomes built into humans/culture. | F10: Tier 2 | G10: =COUNTIF('Master Matrix'!$L:$L,"Tier 2") -> 14 | H10: Plausible comparative reading; source pass required. | J10: Poor fit | K10: =COUNTIF('Master Matrix'!$AC:$AC,"Poor fit") -> 0 | N10: Medieval / early-modern literary | O10: =COUNTIF('Master Matrix'!$AE:$AE,N10) -> 4
A11: DF-01 | B11: Demonized Feminine / Unadministrable Woman | C11: =COUNTIF('Master Matrix'!$B:$B,A11) -> 5 | D11: Female generative, sexual, birth/death, land, or sovereign power is monstered or split. | F11: Tier 3 | G11: =COUNTIF('Master Matrix'!$L:$L,"Tier 3") -> 0 | H11: Deep speculative rope bridge; do not carry argument alone. | J11: Counterexample | K11: =COUNTIF('Master Matrix'!$AC:$AC,"Counterexample") -> 7 | N11: Later literary reception | O11: =COUNTIF('Master Matrix'!$AE:$AE,N11) -> 1
A12: TR-01 | B12: Trickster / Unauthorized Intelligence | C12: =COUNTIF('Master Matrix'!$B:$B,A12) -> 5 | D12: Boundary-crosser uses cunning, theft, humor, or loopholes to move culture forward. | J12: Not yet tested | K12: =COUNTIF('Master Matrix'!$AC:$AC,"Not yet tested") -> 51 | N12: Mixed — separate layers | O12: =COUNTIF('Master Matrix'!$AE:$AE,N12) -> 10
A13: SC-01 | B13: Scapegoat / Founding Violence | C13: =COUNTIF('Master Matrix'!$B:$B,A13) -> 3 | D13: A body absorbs social violence; murder or expulsion stabilizes the group. | N13: Project invention | O13: =COUNTIF('Master Matrix'!$AE:$AE,N13) -> 0
A14: FM-01 | B14: Flood / Reset Memory | C14: =COUNTIF('Master Matrix'!$B:$B,A14) -> 3 | D14: Water catastrophe or social reset becomes moral/cosmic narrative. | J14: Untested share | K14: =IFERROR(K12/COUNTA('Master Matrix'!$A$2:$A$200),"") -> 0.60714286 | N14: Legacy — not yet tagged | O14: =COUNTIF('Master Matrix'!$AE:$AE,N14) -> 53
A15: SG-01 | B15: Sacred Geography / Land Claim | C15: =COUNTIF('Master Matrix'!$B:$B,A15) -> 1 | D15: Mountain, spring, cave, grove, river, or boundary becomes divine proof of belonging. | J15: Read this block as an audit gap, not a score. A cluster with no Poor fit and no Counterexample has not been tested against anything.
A16: DT-01 | B16: Death-Admin / Refusal of Closure | C16: =COUNTIF('Master Matrix'!$B:$B,A16) -> 6 | D16: Underworld, judgment, resurrection, or return prevents power from having final say. | N16: Legacy rows remain explicitly queued for evidence-mode backfill; they are not silently treated as primary-text core.
A17: BW-01 | B17: Birth Threshold / Warding Power | C17: =COUNTIF('Master Matrix'!$B:$B,A17) -> 1 | D17: Childbirth, infant death, disease, milk, and postpartum danger are personified and ritually managed.
A18: AD-01 | B18: Asha / Druj Functional Lens | C18: =COUNTIF('Master Matrix'!$B:$B,A18) -> 3 | D18: Not good vs evil: coherence/truth-pattern versus distortion/rupture, including lawful distortion.
A19: CC-01 | B19: Sacred Contract / Covenant Capture | C19: =COUNTIF('Master Matrix'!$B:$B,A19) -> 3 | D19: Contract/oath/debt ported into the sacred and made permanent; mandatory interpreter. Founding row CC-001.
A20: UF-01 | B20: Uncontained / Co-opted Feminine | C20: =COUNTIF('Master Matrix'!$B:$B,A20) -> 8 | D20: Power too total to split — venerated, harnessed (sacred-marriage kingship), or left as paradox; the co-option pole DF-01 was conflating. Inanna (UF-001), Kali (UF-002).
A21: DV-01 | B21: Divination / Gatekeeping the Divine Will | C21: =COUNTIF('Master Matrix'!$B:$B,A21) -> 4 | D21: Divination as the mandatory-interpreter gate: tamītu (binary query), Delphi (ambiguous utterance), Rome (state veto), Shang (royal monopoly)
A22: DR-01 | B22: Distributed Remainder / Surviving the Center's Fall | C22: =COUNTIF('Master Matrix'!$B:$B,A22) -> 3 | D22: Counterpoint: signal survives a center's fall by distributing (Pharisees, Reformation, post-Buddha) — then re-concentrates
A23: VA-01 | B23: Voice / Authorship / Signal Capture | C23: =COUNTIF('Master Matrix'!$B:$B,A23) -> 7 | D23: Origin, repetition, transmission, record, credibility, and circulation are separate controls.
A24: TH-01 | B24: Threshold / Exit / Jurisdiction | C24: =COUNTIF('Master Matrix'!$B:$B,A24) -> 8 | D24: Real gates, passage rules, exit costs, route closure, escort, and jurisdiction conflict.
A25: CO-01 | B25: Capture by Office / Promotion | C25: =COUNTIF('Master Matrix'!$B:$B,A25) -> 6 | D25: Prior disruption plus offered title/honor: test neutralization against real inclusion and counterexamples.
A26: Immediate Work Queue
A27: Step | B27: Task | C27: Target Sheet | D27: Done? | E27: Notes
A28: 1 | B28: Run PB-01 cluster through MR-01 and MR-04 | C28: Model Run Prompts | E28: Start with Tiamat/Ymir/Tlaltecuhtli/Purusha/Pangu.
A29: 2 | B29: Do source pass for Enuma Elish + Atrahasis | C29: Source Pass Queue | E29: Lock the strongest Mesopotamian rows first.
A30: 3 | B30: Build Mesoamerican lane | C30: Regional Lanes | E30: Separate Nahua/Mexica from Maya; do not flatten.
A31: 4 | B31: Add source URLs/citations | C31: Master Matrix | E31: Primary source first; secondary source second.
A32: 5 | B32: Downgrade or remove weak parallels | C32: Model Review Log | E32: Counterexamples improve the matrix.

Sheet Master Matrix
A1: ID | B1: Cluster ID | C1: Cluster Name | D1: Sub-type / Capture Mode | E1: Tradition / Region | F1: Figure / Myth | G1: Surface Story | H1: Monkey-Politics Read | I1: Priesthood-Function Move | J1: Remainder / What Survives | K1: Primary Parallels | L1: Confidence Tier | M1: Verification Status | N1: Notes / Warnings | O1: Source Anchor | P1: Primary Text / Artifact to Verify | Q1: Passage / Lines Needed | R1: Secondary Scholarship Lead | S1: Model Review Prompt | T1: Model Notes | U1: Overclaim Risk | V1: Next Action | W1: Source URL / Citation | X1: Last Reviewed | Y1: Motif Evidence Tier | Z1: Interpretation Tier | AA1: Row Status | AB1: Predicted-But-Absent (frame test) | AC1: Fit Verdict | AD1: Strongest Counter-Reading | AE1: Evidence Mode | AF1: Adaptation Boundary / Project Invention | AG1: Secondary Cluster(s)
A2: PB-001 | B2: PB-01 | C2: Primordial Body / Corpse-World | E2: Babylonian / Mesopotamian | F2: Tiamat | G2: Sea/chaos mother defeated by Marduk; her body becomes ordered cosmos. | H2: Prior generative order is demonized and butchered by the new regime. | I2: Narrative heist: violence becomes cosmic order and kingly legitimacy. | J2: Chaos/sea/mother power remains as the buried body of the world. | K2: Ymir; Tlaltecuhtli; Leviathan/Yam; Vritra | L2: Tier 1-2 | M2: Anchored (v0.20); tablet/line refs entered, primary NOT opened in-edition | N2: Use as a structural comparator, not proof of one origin. [v0.20 source-pass] Ee IV is a clean anchor for corpse -> cosmos. The body -> landscape detail sits on Tablet V, the epic's most damaged tablet: do not quote V without checking the lacunae. Tiers untouched. | O2: MFM §7; PF case study 1 | P2: Enuma Elis, Tablet IV (killing and splitting) + Tablet V (body -> cosmic features). Critical edition: Lambert 2013. Translation: Dalley 2000. | Q2: Ee IV 93-104 (net, winds, arrow); IV 129-132 (skull smashed with the mace, arteries severed); IV 135-140 (corpse surveyed, split 'like a dried fish', one half raised as the sky, skin stretched with guards posted to hold the waters back); IV 137-146 attested as the heavens-from-corpse passage. Tablet V for the body -> landscape mapping (rivers from the eyes, mountains from the breasts). IV lines are securely attested; V lines are NOT - Tablet V is the most damaged tablet in the epic and partly reconstructed from a Sultantepe duplicate. Confirm what survives before quoting V. | R2: Lambert, W. G., Babylonian Creation Myths (Eisenbrauns, 2013) = standard critical edition. Dalley, S., Myths from Mesopotamia, rev. ed. (OUP, 2000) = working translation. Talon, SAACT 4. eBL (electronic Babylonian Library) for the composite text and line numbering. | S2: Use MR-01 + MR-03 | U2: Medium until source pass complete | V2: Run model review, then source-pass [v0.20 source-pass] Open Lambert 2013 / eBL and pin exact V lines. Then M -> Sourced. | W2: Lambert 2013, Babylonian Creation Myths, Eisenbrauns | Dalley 2000, Myths from Mesopotamia, OUP: Tablet I at p. 234, Tablet II at pp. 243-244, Tablet VI at p. 261 (pages verified via secondary quotation, not opened in-edition) | X2: 2026-07-29 | Y2: Tier 1 | Z2: Tier 1-2 | AA2: Load-bearing | AB2: None identified. Corpse -> cosmos and the state-ritual use are both present in the primary. | AC2: Fits | AD2: The 'conquest of the feminine' reading is contested. Tiamat may function as an undifferentiated cosmological principle rather than a displaced political predecessor, and she is sympathetic in Tablet I - monstrous only after provocation. That cuts against reading her as demonised from the outset. | AE2: Legacy — not yet tagged
A3: PB-002 | B3: PB-01 | C3: Primordial Body / Corpse-World | E3: Norse | F3: Ymir | G3: Primordial giant killed by Odin and brothers; body becomes world. | H3: Older giant/ancestor body is converted into divine infrastructure. | I3: Embedded remainder: old body becomes foundation of new order. | J3: Jötnar remain kin/enemy; prior order is never fully erased. | K3: Tiamat; Tlaltecuhtli; Purusha; Pangu | L3: Tier 1-2 | M3: Needs source pass | N3: Not the same deity as Tiamat; same function cluster. | O3: Comparative candidate | P3: TBD: identify primary text/artifact | Q3: TBD: exact passage, tablet, chapter, hymn, codex plate, or oral-transcription source | R3: TBD: one reputable secondary source | S3: Use MR-01 + MR-03 | U3: Medium until source pass complete | V3: Run model review, then source-pass | Y3: Tier 1 | Z3: Tier 2 | AA3: Supportive | AB3: No state cult, no ritual re-performance, no institution shown using the Ymir cosmogony for legitimation. PB-01's political-capture half is absent; only the body -> world half is present. | AC3: Partial fit | AD3: Snorri's Gylfaginning is c. 1220 CE, roughly two centuries after Iceland's conversion, and is a Christian antiquarian systematising fragmentary verse. The tidiness of the corpse-world mapping may be Snorri's. Vafthrudnismal is the older witness - check what it actually supports before the row carries weight. | AE3: Legacy — not yet tagged
A4: PB-003 | B4: PB-01 | C4: Primordial Body / Corpse-World | E4: Nahua / Mexica | F4: Tlaltecuhtli | G4: Earth body/monster is torn apart or transformed to form habitable earth. | H4: Living earth-body is converted into land/infrastructure. | I4: Body-world creates ritual debt: the earth must be fed/maintained. | J4: Earth remains alive, hungry, and ritually demanding. | K4: Tiamat; Ymir; Coatlicue; Coyolxauhqui | L4: Tier 1-2 | M4: Partial; Graulich verified; Histoire du Mechique folio owed | N4: Mesoamerican lane: likely crucial for body-world + ritual debt. [v0.19.1 source-pass] Colonial witnesses. Graulich 1983 verified (confirm 'killed vs left alive' detail before quoting); Histoire du Mechique folio still owed. Support: partial. Tier unchanged. | O4: Comparative candidate | P4: Historia de los mexicanos por sus pinturas (Cipactli -> earth -> Tlaltecutli); Histoire du Mechique (de Jonghe ed.) for the tearing-in-two. | Q4: Hist. de los mexicanos ch. 2 paras 22 & 29; Histoire du Mechique folio NOT pinned (still owed). | R4: Graulich, 'Myths of Paradise Lost in Pre-Hispanic Central Mexico,' Current Anthropology 24:5 (1983): 575-588. [VERIFIED - confirm the 'killed vs left alive' point before quoting] | S4: Use MR-01 + MR-03 | U4: Medium until source pass complete | V4: Run model review, then source-pass [v0.19] Source-pass: source via colonial intermediary (Histoyre du Mechique); pin + living-tradition care (Nahua packet). | W4: Graulich 1983, Current Anthropology 24(5):575-588. doi.org/10.1086/203063 | Y4: Tier 2 | Z4: Tier 2 | AA4: Source-pass | AC4: Not yet tested | AE4: Legacy — not yet tagged
A5: PB-004 | B5: PB-01 | C5: Primordial Body / Corpse-World | E5: Vedic | F5: Purusha | G5: Cosmic being sacrificed; world and social order emerge from body. | H5: Sacrificial body becomes cosmos and social hierarchy. | I5: Sacrifice naturalizes order; body-politic becomes sacred structure. | J5: Social divisions persist as parts of a cosmic body. | K5: Ymir; Pangu; Tiamat; caste/body-politic patterns | L5: Tier 1-2 | M5: Needs source pass | N5: Watch caste/order claims carefully; do not overflatten devotional meaning. | O5: Comparative candidate | P5: TBD: identify primary text/artifact | Q5: TBD: exact passage, tablet, chapter, hymn, codex plate, or oral-transcription source | R5: TBD: one reputable secondary source | S5: Use MR-01 + MR-03 | U5: Medium until source pass complete | V5: Run model review, then source-pass [v0.19.1] Raised Source-pass -> Supportive: RV 10.90 anchor is clean enough; interpretation still capped at Tier 2. | Y5: Tier 1 | Z5: Tier 2 | AA5: Supportive | AB5: No conquest, no adversary, no coup. The sacrifice is voluntary and self-generated, so PB-01's 'prior order destroyed by a new regime' element is missing entirely. | AC5: Partial fit | AD5: RV 10.90 is generally held to be among the latest hymns in the Rig Veda. The varna verse may record an emergent ritual homology rather than the codified caste order later read back into it. Verify with a Vedic specialist before this row supports any capture claim. | AE5: Legacy — not yet tagged
A6: PB-005 | B6: PB-01 | C6: Primordial Body / Corpse-World | E6: Chinese | F6: Pangu | G6: Primordial being separates heaven and earth; body becomes world after death. | H6: Cosmic body becomes infrastructure with less overt coup/murder. | I6: Softer body-world form; world-order emerges from prior body. | J6: Body parts persist as features of world. | K6: Ymir; Purusha; Tiamat | L6: Tier 2 | M6: Needs source pass | N6: Lower violence than Tiamat/Ymir; same architecture, different mood. [v0.19] Soft body-world comparator: no murder/coup/demonization - do NOT let it carry the capture argument. | O6: Comparative candidate | P6: TBD: identify primary text/artifact | Q6: TBD: exact passage, tablet, chapter, hymn, codex plate, or oral-transcription source | R6: TBD: one reputable secondary source | S6: Use MR-01 + MR-03 | U6: Medium until source pass complete | V6: Run model review, then source-pass [v0.19.1] Dropped Supportive -> Source-pass (soft comparator only): Interp Tier 3 cannot be Supportive/Load-bearing; must not carry the capture argument. | Y6: Tier 2 | Z6: Tier 3 | AA6: Source-pass | AB6: No murder, no adversary, no subordinated remainder, no legitimated ruler. Every element of PB-01's diagnostic except 'body becomes world' is absent. | AC6: Counterexample | AD6: The honest reading is that body -> world cosmogony does not require a capture event - which is what this row demonstrates. NOTE: the 'same architecture, different mood' gloss in col N absorbs the mismatch instead of scoring it. Treat that gloss as the frame protecting itself. | AE6: Legacy — not yet tagged
A7: OO-001 | B7: OO-01 | C7: Ordering Operator / New Boss | E7: Babylonian / Mesopotamian | F7: Marduk | G7: Defeats Tiamat, organizes cosmos, receives supremacy among gods. | H7: Young military/executive operator converts crisis into permanent sovereignty. | I7: Emergency powers become kingly order; state-temple legitimation. | J7: Defeated older order persists as the world he rules. | K7: Odin; Indra; Baal; Tezcatlipoca/Quetzalcoatl | L7: Tier 1-2 | M7: Anchored (v0.20); STRONG - the irrevocability clause is explicit in the text | N7: Best anchor for narrative heist / hostile takeover reading. [v0.20 source-pass] FINDING: OO-01's core diagnostic ('crisis converted into permanent sovereignty') is explicit in the primary text, not inferred. Marduk's condition includes a no-revocation clause, and the assembly grants it in advance of the battle. Recommend the motif tier be reviewed upward next pass; NOT changed here, per the discipline that a source pass does not re-tier. Akitu recitation supplies the state-ritual context. | O7: MFM §7; PF case study 1 | P7: Enuma Elis, Tablet II (Marduk's terms) + Tablet IV 1-34 (the assembly grants them) + Tablet VI-VII (kingship, Babylon, the fifty names). | Q7: Ee II: Marduk's price - convene the assembly, fix a special fate, 'my own utterance shall fix fate instead of you; whatever I decree of my lips shall never be revoked, never changed' (Dalley pp. 243-244; LINE NUMBERS NOT PINNED). Ee IV 1-34: the assembly agrees before the crisis is resolved - 'your destiny is unequalled, your word has the power of Anu' - and tests his word on a constellation. Ee VI 99: kingship over the gods. Ee VI 55, 72: Babylon and Esagila. Ee VII: the fifty names. Context: the epic was recited at the Akitu New Year festival - annual re-performance of the charter. | R7: Lambert, W. G., Babylonian Creation Myths (Eisenbrauns, 2013) = standard critical edition. Dalley, S., Myths from Mesopotamia, rev. ed. (OUP, 2000) = working translation. Talon, SAACT 4. eBL (electronic Babylonian Library) for the composite text and line numbering. On the Akitu recitation and the Ashur recension, check a standard reference. | S7: Use MR-01 + MR-03 | U7: Medium until source pass complete | V7: Run model review, then source-pass [v0.20 source-pass] Pin Ee II line numbers, then propose a tier review for Y (motif). | W7: Lambert 2013, Babylonian Creation Myths, Eisenbrauns | Dalley 2000, Myths from Mesopotamia, OUP: Tablet I at p. 234, Tablet II at pp. 243-244, Tablet VI at p. 261 (pages verified via secondary quotation, not opened in-edition) | X7: 2026-07-29 | Y7: Tier 1 | Z7: Tier 1 | AA7: Load-bearing | AB7: None. The irrevocability clause makes 'crisis converted into permanent sovereignty' explicit rather than inferred. | AC7: Fits | AD7: The Assur recension substitutes Ashur for Marduk, so the charter is portable. That supports reading the epic as a general kingship ideology rather than the record of one historical usurpation - which weakens any specific political-event reading. | AE7: Legacy — not yet tagged
A8: OO-002 | B8: OO-01 | C8: Ordering Operator / New Boss | E8: Norse | F8: Odin + brothers | G8: Kill Ymir and order the world from his body. | H8: Younger divine faction converts primordial ancestor into structured world. | I8: New order stabilizes itself through old body's conversion. | J8: Giant line continues as kin/enemy/remainder. | K8: Marduk; Tezcatlipoca/Quetzalcoatl; Indra | L8: Tier 1-2 | M8: Needs source pass | N8: Odin also carries knowledge, sacrifice, war, death; do not reduce him to Marduk. | O8: Comparative candidate | P8: TBD: identify primary text/artifact | Q8: TBD: exact passage, tablet, chapter, hymn, codex plate, or oral-transcription source | R8: TBD: one reputable secondary source | S8: Use MR-01 + MR-03 | U8: Medium until source pass complete | V8: Run model review, then source-pass | Y8: Tier 1 | Z8: Tier 2 | AA8: Supportive | AC8: Not yet tested | AE8: Legacy — not yet tagged
A9: OO-003 | B9: OO-01 | C9: Ordering Operator / New Boss | E9: Nahua / Mexica | F9: Tezcatlipoca / Quetzalcoatl | G9: Rival operators involved in world-formation, earth-body, and cosmic cycles in variants. | H9: Divine rivals reshape prior earth/monster/body into usable world. | I9: World-order emerges through conflict and ritual maintenance. | J9: Earth/body/monster remains as debt-bearing infrastructure. | K9: Marduk; Odin; Enki/Enlil; Hero Twins | L9: Tier 2 | M9: Composite; flag for split; secondary owed | N9: Handle variants carefully; do source pass before locking row. [v0.19.1 source-pass] Supports solar succession + divine competition, NOT one unified overthrow - composite; flag for split. Secondary still owed. Support: partial. Tier unchanged. | O9: Comparative candidate | P9: Historia de los mexicanos por sus pinturas (Tezcatlipoca/Quetzalcoatl orderings; the Suns). | Q9: Hist. de los mexicanos ch. 2 paras 14-16, 22, 29; ch. 3 para 33; chs. 5-7 (the Suns) - supports solar succession + divine competition, NOT one unified overthrow. | R9: NOT FOUND - secondary still owed. (Graulich 1983, entered at PB-003, bears on the Suns/creation context.) | S9: Use MR-01 + MR-03 | U9: Medium until source pass complete | V9: Run model review, then source-pass [v0.19] Source-pass: composite; pin exact version/source before use (Nahua packet). | W9: Primary to confirm (Hist. de los mexicanos chs. 2-7). Secondary owed. | Y9: Tier 3 | Z9: Tier 3 | AA9: Source-pass | AC9: Not yet tested | AE9: Legacy — not yet tagged
A10: OO-004 | B10: OO-01 | C10: Ordering Operator / New Boss | E10: Vedic | F10: Indra | G10: Defeats Vritra and releases waters. | H10: Storm/war chief breaks hoarder/serpent control of life-resource. | I10: Violence legitimates order by freeing controlled resource. | J10: Serpent/hoarder remains as recurring chaos/resource-control figure. | K10: Baal/Yam; Yahweh/Leviathan; Marduk/Tiamat | L10: Tier 1-2 | M10: Needs source pass | N10: Better as resource-release/chaoskampf than corpse-world. | O10: MFM monster taxonomy; comparative candidate | P10: TBD: identify primary text/artifact | Q10: TBD: exact passage, tablet, chapter, hymn, codex plate, or oral-transcription source | R10: TBD: one reputable secondary source | S10: Use MR-01 + MR-03 | U10: Medium until source pass complete | V10: Run model review, then source-pass | Y10: Tier 1 | Z10: Tier 2 | AA10: Supportive | AC10: Not yet tested | AE10: Legacy — not yet tagged
A11: OO-005 | B11: OO-01 | C11: Ordering Operator / New Boss | E11: Levantine / Biblical poetic | F11: Baal / Yahweh storm-war motifs | G11: Storm/king god defeats sea, dragon, Leviathan/Rahab/Yam in poetic or mythic material. | H11: Rule legitimized by victory over unadministered sea/chaos/resource. | I11: Chaoskampf becomes sacred kingship/order language. | J11: Sea/dragon imagery persists as recurring threat. | K11: Marduk/Tiamat; Indra/Vritra; Zeus/Typhon | L11: Tier 1-2 | M11: Cut/Merge - inactive; leads only, nothing Sourced | N11: Avoid flattening distinct traditions; compare motif, not identity. [v0.19.1 source-pass] Nothing verified to enter. Stays Cut/Merge / INACTIVE until split. GPT's pointers (Baal Cycle KTU/CAT; Ps 74, 89, Isa 27, Job 26) are LEADS for the split, not sources - do not mark Sourced. | O11: MFM §7 / Chaoskampf | P11: Leads only (NOT sources): Baal Cycle KTU/CAT 1.1-1.6 (Ugaritic); Ps 74, Ps 89, Isa 27:1, Job 26 (Yahweh storm-war) - for the eventual Baal vs Yahweh split. | Q11: (n/a - inactive until split) | R11: Leads only; nothing verified to enter as a secondary. | S11: Use MR-01 + MR-03 | U11: Medium until source pass complete | V11: Run model review, then source-pass [v0.19] SPLIT: separate into Baal (Ugaritic Baal Cycle) and Yahweh storm-war as parallel rows; do not cite as one figure. [v0.19.1] INACTIVE - do not cite as a live row until split into Baal and Yahweh storm-war parallels. | W11: (none - inactive until split) | Y11: Tier 2 | Z11: Tier 2 | AA11: Cut/Merge | AC11: Not yet tested | AE11: Legacy — not yet tagged
A12: RF-001 | B12: RF-01 | C12: Rebel Blood / Embedded Remainder | D12: rebel-blood | E12: Babylonian / Mesopotamian | F12: Kingu | G12: Rebel/consort killed; blood used to create humanity as labor force. | H12: Defeated refusal becomes material foundation of worker species. | I12: Embedded remainder: the rebel is killed, then built into the system. | J12: Humanity carries the blood/material of the refuser while assigned obedience. | K12: Prometheus; Azazel; sacrificed founding victims | L12: Tier 1-2 | M12: Anchored (v0.20); Lambert 287 supplies a real counter-detail - see counter-reading | N12: One of the strongest project nodes. [v0.20 source-pass] FINDING with teeth: Lambert notes the assembly's charge that Qingu made Tiamat rebel has no antecedent anywhere earlier in the epic. The guilt is retroactive. This is strong support for the embedded-remainder reading AND makes the row structurally a scapegoat case - it belongs to SC-01 as much as RF-01. Consider cross-referencing rather than a single home. | O12: PF case study 1 | P12: Enuma Elis, Tablet VI 1-46. Compare Atra-hasis I (parallel anthropogeny). | Q12: Ee VI 1-8: Marduk's plan - 'let me put blood together and make bones too... the work of the gods shall be imposed on him, and so they shall be at leisure' (VI 8 = the labour-imposition line). Ee VI 29-34: the assembly charges Qingu, he is bound, his blood vessels severed, mankind fashioned from his blood; VI 33-34 attested as 'Ea created mankind, on whom he imposed the service of the gods, and set the gods free'. Ee VI 43-46: organisation of the netherworld and stations of the gods. | R12: Lambert, W. G., Babylonian Creation Myths (Eisenbrauns, 2013) = standard critical edition. Dalley, S., Myths from Mesopotamia, rev. ed. (OUP, 2000) = working translation. Talon, SAACT 4. eBL (electronic Babylonian Library) for the composite text and line numbering. Lambert 2013 pp. 101, 111, 113 on the Qingu passages and p. 287 on the unsupported charge (page refs taken from a secondary index - confirm in-edition). Krebernik on Enlil/Ninurta forerunners. | S12: Use MR-01 + MR-03 | U12: Medium until source pass complete | V12: Run model review, then source-pass [v0.20 source-pass] Confirm Lambert p. 287 in-edition; propose RF-001 <-> SC-01 cross-reference. | W12: Lambert 2013, Babylonian Creation Myths, Eisenbrauns | Dalley 2000, Myths from Mesopotamia, OUP: Tablet I at p. 234, Tablet II at pp. 243-244, Tablet VI at p. 261 (pages verified via secondary quotation, not opened in-edition) | Lambert 2013 pp. 101, 111, 113, 287 [page refs via secondary index] | X12: 2026-07-29 | Y12: Tier 1 | Z12: Tier 1 | AA12: Load-bearing | AB12: None. The remainder is literally the construction material. | AC12: Fits | AD12: Lambert notes the charge against Qingu has no antecedent earlier in the epic: the guilt is retroactive. This strengthens the reading but relocates the row - it is structurally a scapegoat case, so SC-01 has as good a claim on it as RF-01. | AE12: Legacy — not yet tagged
A13: RF-002 | B13: RF-01 | C13: Rebel Blood / Embedded Remainder | D13: stolen-fire | E13: Greek | F13: Prometheus | G13: Steals/gives fire to humans; punished by Zeus. | H13: Unauthorized tech transfer breaks elite monopoly. | I13: State/order punishes independent knowledge worker. | J13: Fire/culture remains with humans despite punishment. | K13: Azazel; Watchers; Māui; Raven; Hephaestus/Wayland | L13: Tier 1-2 | M13: Needs source pass | N13: Technology taboo + captured craftsman cluster. | O13: MFM §5A | P13: TBD: identify primary text/artifact | Q13: TBD: exact passage, tablet, chapter, hymn, codex plate, or oral-transcription source | R13: TBD: one reputable secondary source | S13: Use MR-01 + MR-03 | U13: Medium until source pass complete | V13: Run model review, then source-pass | Y13: Tier 1 | Z13: Tier 1-2 | AA13: Supportive | AC13: Not yet tested | AE13: Mixed — separate layers | AF13: Keep Hesiod and Prometheus Bound separate. The dangerous-marriage secret is tragic-layer evidence; a modern whistleblower trial is invention. | AG13: VA-01
A14: RF-003 | B14: RF-01 | C14: Rebel Blood / Embedded Remainder | D14: fallen-watchers | E14: Enochic Jewish | F14: Azazel / Watchers | G14: Teach forbidden crafts; descend and produce destabilizing offspring; punished. | H14: Elite/outsider knowledge and sexual access become demonized. | I14: Forbidden craft is managed by later moral/theological frame. | J14: Technical knowledge and hybrid anxiety remain inside human culture. | K14: Prometheus; Hephaestus; Apkallu; Nephilim | L14: Tier 1-2 | M14: Needs source pass | N14: Distinguish textual Enoch from later demonology. | O14: MFM §5 / §5A | P14: TBD: identify primary text/artifact | Q14: TBD: exact passage, tablet, chapter, hymn, codex plate, or oral-transcription source | R14: TBD: one reputable secondary source | S14: Use MR-01 + MR-03 | U14: Medium until source pass complete | V14: Run model review, then source-pass | Y14: Tier 1 | Z14: Tier 2 | AA14: Supportive | AC14: Not yet tested | AE14: Legacy — not yet tagged
A15: RF-004 | B15: RF-01 | C15: Rebel Blood / Embedded Remainder | D15: culture-hero | E15: Polynesian | F15: Māui | G15: Trickster/culture hero obtains fire, slows sun, fishes land, or alters cosmic conditions. | H15: Unauthorized intelligence modifies world-order for human use. | I15: System cannot stop useful theft/innovation from becoming culture. | J15: Human world carries trickster alterations. | K15: Prometheus; Raven; Coyote; Quetzalcoatl | L15: Tier 2 | M15: Needs source pass | N15: Variant-heavy; source specific islands/traditions. | O15: Comparative candidate | P15: TBD: identify primary text/artifact | Q15: TBD: exact passage, tablet, chapter, hymn, codex plate, or oral-transcription source | R15: TBD: one reputable secondary source | S15: Use MR-01 + MR-03 | U15: Medium until source pass complete | V15: Run model review, then source-pass [v0.19] Source-pass: needs named iwi/tradition + collector; no pan-Polynesian flattening. | Y15: Tier 2 | Z15: Tier 2 | AA15: Source-pass | AC15: Not yet tested | AE15: Legacy — not yet tagged
A16: RF-005 | B16: RF-01 | C16: Rebel Blood / Embedded Remainder | D16: culture-hero | E16: Pacific Northwest / Indigenous North American | F16: Raven | G16: Steals or releases light/fire; transforms world through cunning. | H16: Low-status or liminal intelligence brings culture by theft. | I16: Unauthorized acquisition becomes origin of human possibility. | J16: Light/fire/world-order remains despite trickster mess. | K16: Prometheus; Māui; Coyote; Anansi | L16: Tier 2 | M16: Secondary verified; stays Quarantine | N16: Must name specific tribal/version sources later. [v0.19.1 source-pass] Tie to Tlingit/Wrangell specifically; do NOT generalize as 'the Raven myth.' Thornton & Thornton 2015 verified (use FULL title; GPT gave only the subtitle). Stays Quarantine (handling discipline, K10). Motif Tier 3 = row-format/source-flattening, not denial of the motif in Tlingit sources. Support: partial (strong for this version). Tier unchanged. | O16: Comparative candidate | P16: Swanton, Tlingit Myths and Texts (BAE Bulletin 39, 1909) - Wrangell Raven (daylight-box release; distribution of water). | Q16: Wrangell Raven cycle - confirm exact myth number in Swanton 1909. | R16: Thornton & Thornton, 'The Mutable, the Mythical, and the Managerial: Raven Narratives and the Anthropocene,' Environment and Society 6:1 (2015): 66-86. [VERIFIED - full title] | S16: Use MR-01 + MR-03 | U16: Medium until source pass complete | V16: Run model review, then source-pass [v0.19] QUARANTINE: do not use until tied to a named nation/version/collector. [v0.19.1] Motif Tier 3 reflects row-format/source-flattening, not denial of the motif in specific nations. | W16: Thornton & Thornton 2015, Environment and Society 6(1):66-86. doi.org/10.3167/ares.2015.060105 | Y16: Tier 3 | Z16: Tier 3 | AA16: Quarantine | AC16: Not yet tested | AE16: Legacy — not yet tagged
A17: RF-006 | B17: RF-01 | C17: Rebel Blood / Embedded Remainder | D17: crippled-maker | E17: Greek (Hephaestus) / cf. Roman Vulcan | F17: Hephaestus — lame smith of Olympus, cast from heaven, mocked and cuckolded by the gods, yet sole maker of all their arms, palaces, and wonders. | G17: Born lame (Homer) — or crippled by the fall when Zeus seizes his leg and hurls him from Olympus for siding with Hera. He lands on Lemnos, returns, and becomes the indispensable artificer: Achilles' armour, Hermes' winged gear, Zeus's aegis, self-moving automatons, the gods' very halls. Forced to wed Aphrodite (to head off a war over her), he is cuckolded by Ares; when he nets the lovers, the gods laugh — at him. | H17: The one who actually MAKES the tools of power is kept structurally low — marked as defective, mocked, denied the status his output earns. The coalition extracts the maker's product while withholding rank; his deformity is the badge that licenses the extraction. But the maker holds quiet leverage no one else has: he makes the chair Hera can't rise from and the net Ares can't break — the one who forges the bindings can bind the bosses. | I17: His craft is absorbed into the order as ITS glory (the gods' arsenal is 'theirs') while he is framed as the comic, ugly, subordinate exception — the value canonized upward, the maker written down. The forced marriage and the laughter are the social machinery that keeps the indispensable producer in his place. | J17: The whole material order of Olympus is HIS work — the remainder is everywhere, embedded in every divine object. And the leverage keeps leaking: the trap-chair extracts a concession from Hera, the net publicly shames the war-god, and he is one of the few exiles who returns. The maker can't be fully written down because the order literally runs on what he alone can make. | K17: Wayland (RF-007, the lamed maker captured by a king); Tubal-Cain (RF-008); Prometheus (RF-002, fire/craft punished); Athena (UF-003 — Zeus's perfect head-born daughter vs Hera's crippled solo son) | L17: Tier 1-2 | M17: Sourced (this pass) | N17: Two origin-versions of the lameness (congenital vs caused-by-fall) — don't collapse them; Homer uses both inconsistently. The 'maker's leverage' reading is Tier 2 but rests on textual episodes (the chair, the net). The Athena cross-link via Hurwit's patriarchal-asymmetry point is itself a scholarly reading; cite it as such. | O17: MFM §5A (smith & technology taboo) — captured-maker pole. PF §1, §3 (capture, embedded remainder). Sub-cluster with Wayland. | P17: Homer, Iliad I.586-594 (Zeus hurls him; lands on Lemnos) and XVIII.368-617 (forging Achilles' armour; he recalls Hera casting him out 'shamed by my lameness'); Odyssey 8.266-366 (Ares/Aphrodite net). | Q17: Iliad I.590-600 (the fall + the gods' laughter as he serves nectar); Iliad XVIII.394-409 (Hera's rejection); Od. 8.266-366 (the net). | R17: J.M. Hurwit on the Hera/Zeus birth-asymmetry (perfect Athena vs crippled Hephaestus); Marie Delcourt, 'Hephaistos ou la legende du magicien' (1957); theoi.com compendium s.v. Hephaistos. | S17: Is 'maker's leverage' textual or romanticized? Verify the chair and net episodes; confirm the indispensability claim (range of objects he makes); keep the two lameness-versions distinct. | U17: MODERATE — the subordination-of-the-maker reading is well-grounded, but don't over-read the 'rebellion' (his leverage is real yet limited; he largely stays inside the order, unlike Wayland). Avoid treating Vulcan=Hephaestus syncretism as identity. | V17: Pull Iliad I + XVIII and Od. 8 line refs (Lattimore/Fagles); confirm Hurwit citation; mark the Athena cross-link as a scholarly reading. | W17: poetryintranslation.com Iliad XVIII; theoi.com/Olympios/Hephaistos; en.wikipedia.org/wiki/Hephaestus (Homer Il. I.586ff, XVIII; Od. 8) | X17: 2026-06-14 | Y17: Tier 1 | Z17: Tier 2 | AA17: Supportive | AC17: Not yet tested | AE17: Mixed — separate layers | AF17: Hephaestus's reluctant enforcement labor, divine status, workshop autonomy, and variant ejection stories must not be harmonized.
A18: RF-007 | B18: RF-01 | C18: Rebel Blood / Embedded Remainder | D18: enslaved-maker | E18: Norse / Germanic / Anglo-Saxon; Völundarkviða (Poetic Edda) | F18: Wayland / Völundr — master smith captured by a king, deliberately hamstrung to keep him producing, who works his revenge entirely through his craft and escapes on self-forged wings. | G18: King Niðhad, envious of Völundr's skill and treasures, seizes him in his sleep, has his hamstrings cut so he cannot flee, and imprisons him on an island to forge for the crown. The king wears Völundr's stolen sword; the princess wears his stolen ring. Völundr lures the king's two sons to the smithy, kills them, and reforges their skulls into goblets, eyes into jewels, teeth into a brooch — gifts sent unwitting to the royal family. He rapes and impregnates the princess, then flies away on wings he has made, taunting the king from the air. | H18: Power that cannot generate the craft itself seizes the body that can and MAIMS it precisely to bind it to production — the crippling is the control mechanism, not an accident. The king appropriates the maker's output (sword, ring) as his own household's adornment. But a bound maker is the most dangerous thing in the workshop: the only hands that can make the king's treasures can also make his catastrophe. | I18: Capture-and-extract in its rawest form — no canonizing theology, just force: enslave the producer, take the product, display it as the crown's. The 'gifts' the maker sends back are the move turned inside out — the order consumes and wears the maker's craft without knowing what it now contains. | J18: The remainder is monstrous and literal — the king eats from goblets made of his own sons, the queen wears their eyes, the princess a brooch of their teeth: the maker's embedded product is the captor's own undoing, hidden in plain sight. And the maker escapes intact via a made object (the wings); the craft meant to bind him is exactly what frees him. In Deor he is remembered as suffering endured and overcome. | K18: Hephaestus (RF-006, the other lamed captured maker — but Hephaestus stays inside the order; Wayland razes it); Tubal-Cain (RF-008); Prometheus (RF-002) | L18: Tier 1-2 | M18: Sourced (this pass) | N18: Brutal content (filicide, rape) — represent plainly, don't aestheticize. Source versions differ (Völundarkviða vs Þiðrekssaga's Velent), but the hamstringing-to-enslave core is constant. The 'crippling AS control' reading is strongly textual here (unlike Hephaestus, where lameness is congenital/accidental). | O18: MFM §5A (smith & technology taboo) — captured-maker pole, violent variant. PF §1 (capture), §3 (embedded remainder). Sub-cluster with Hephaestus. | P18: Völundarkviða (Poetic Edda) — full lay; Þiðrekssaga (Velent episode); Old English Deor (Welund stanza); depicted on the Franks Casket and Ardre stone VIII. | Q18: Völundarkviða strophes on the capture + hamstringing (Niðhad seizes him, cuts the sinews, sets him to the forge) through the revenge and winged escape; Deor ll. 1-13 (Welund's torment). | R18: Ursula Dronke (ed.), 'The Poetic Edda' Vol. II (Mythological Poems), edition + commentary on Völundarkviða; John McKinnell on the smith-legend; Leslie Webster on the Franks Casket. | S18: Confirm the hamstringing-to-prevent-escape and forced-labour framing are explicit in Völundarkviða (Dronke). Distinguish Eddic vs Þiðrekssaga versions. Keep the violence factual, not lurid. | U18: LOW-MODERATE — the captured-and-crippled-maker reading is about as directly textual as the cluster gets; main risk is importing a tidy 'craft-as-liberation' moral the bleak poem doesn't endorse (the escape leaves devastation, not justice). | V18: Pull Dronke's Völundarkviða strophe numbers; cite the Deor stanza; note the Franks Casket panel as material attestation. | W18: en.wikipedia.org/wiki/Wayland_the_Smith; vikingtimes.co.uk Völundarkviða (Poetic Edda; Deor; Þiðrekssaga) | X18: 2026-06-14 | Y18: Tier 1 | Z18: Tier 1 | AA18: Load-bearing | AC18: Not yet tested | AE18: Legacy — not yet tagged
A19: RF-008 | B19: RF-01 | C19: Rebel Blood / Embedded Remainder | D19: marked-lineage | E19: Hebrew Bible (Genesis); later Jewish/Christian interpretation | F19: Tubal-Cain — the Bible's first smith, 'forger of all instruments of bronze and iron,' whose craft is located in the cursed line of Cain rather than the godly line of Seth. | G19: Genesis 4:22 names Tubal-Cain, son of Lamech and Zillah, seventh from Cain, as the originator of metalworking — 'the forger of all instruments of bronze and iron.' His half-siblings are eponyms of the other arts: Jabal (herding/tents), Jubal (the lyre and pipe), with Naamah (weaving, in tradition). The whole technical-cultural toolkit is credited to the Cainite branch, immediately before Lamech's boast of killing and the Flood that wipes the line. | H19: Here the capture is GENEALOGICAL, not physical — no maker is bound, but the craft itself is assigned a bloodline. The dangerous, powerful knowledge (metal = tools AND weapons) is filed under the marked, violent lineage, quarantining the technology by tainting its source. Civilization's indispensable arts are acknowledged and simultaneously fenced off as belonging to the wrong, cursed branch of humanity. | I19: The taboo move: credit the craft, mark the craftsman's line. Later interpretation makes it explicit — Philo reads the metalwork as the 'iron passions' culminating Cain's violence; the placement next to Lamech's blood-boast and before the Flood frames metallurgy as belonging to the doomed, not the saved. The remainder (everyone keeps using metal) is licensed only after the source is morally cordoned. | J19: The craft outlives its quarantine completely — post-Flood humanity still forges, so the knowledge is plainly indispensable and embedded in all later culture; what the narrative retains is only the STAIN on its origin. The smith stays ambivalent ever after: Eliade reads the furnace as sacred rebirth (ore->refined), the same craft both holy and cursed. | K19: Hephaestus (RF-006 — later writers literally identify Tubal-Cain with Vulcan; sister Naamah ~ Venus); Wayland (RF-007); Prometheus (RF-002, gift that is also transgression); Azazel/Watchers (RF-003, forbidden metallurgy/weapon knowledge) | L19: Tier 1-2 | M19: Sourced (this pass) | N19: The 'technology taboo' valence is INTERPRETIVE (Philo onward), NOT stated in the verse — Gen 4:22 itself is fairly neutral, even read positively by some as human skill 'from day one.' Flag the competing reading. This is the §5A taboo POLE, distinct from the captured-maker pole (Tubal-Cain is neither bound nor crippled). Don't confuse with Tubal son of Japheth (Gen 10:2). | O19: MFM §5A (smith & technology taboo) — technology-taboo pole. PF §1, §2 (capture, canonize via genealogy). Sub-type distinct from the captured-maker pair. | P19: Genesis 4:17-24 (the Cainite genealogy; 4:22 Tubal-Cain; 4:23-24 Lamech's boast). Hebrew: loTesh kol-choresh nechosheth u-bharzel. | Q19: Gen 4:22 (the smith) read against 4:23-24 (Lamech's violence) and 4:25-26 (the Sethite alternative); cf. 1 Enoch 8 (Watchers' taught metallurgy). | R19: Philo, 'On the Posterity of Cain'; Mircea Eliade, 'The Forge and the Crucible' (smith ambivalence); Westermann, 'Genesis 1-11'; Gunkel, 'Genesis' (Cainite-vs-Sethite arts). | S19: Separate Tier 1 (verse credits Tubal-Cain with metallurgy) from Tier 2 (the cursed/taboo valence is interpretive). Surface the competing 'neutral/positive' reading. Confirm the seventh-generation and Lamech-boast adjacency. | U19: HIGH if the verse is read as a flat 'metallurgy is cursed' statement — that's a later interpretive layer, and a real counter-tradition reads the Cainite arts as neutral human achievement. The taboo is in the genealogy + reception, not the words. | V19: Confirm Westermann/Gunkel on the Cainite-arts structure; pull the Philo citation; mark the Watchers (1 Enoch 8) cross-link to RF-003. [v0.19.1] Dropped Supportive -> Source-pass: Interp Tier 3 cannot be Supportive/Load-bearing; metallurgy-curse reading needs secondary hardening. | W19: en.wikipedia.org/wiki/Tubal-cain; biblehub.com/genesis/4-22; alc.net.au biblical-forge-of-tubal-cain (Genesis 4:22; Philo; Eliade) | X19: 2026-06-14 | Y19: Tier 1 | Z19: Tier 3 | AA19: Source-pass | AC19: Not yet tested | AE19: Legacy — not yet tagged
A20: DF-001 | B20: DF-01 | C20: Demonized Feminine / Unadministrable Woman | E20: Babylonian / Mesopotamian | F20: Tiamat | G20: Presented as chaos dragon/mother defeated by Marduk. | H20: Prior mother-order is demonized to authorize new male kingship. | I20: Narrative heist: older generative power becomes chaos needing conquest. | J20: Her body remains the world; the demonized feminine is foundational. | K20: Ymir; Tlaltecuhtli; Leviathan; Coyolxauhqui | L20: Tier 1-2 | M20: Anchored (v0.20); tablet/line refs entered, primary NOT opened in-edition | N20: Not 'secretly good'; treat as crime scene / prior order. [v0.19] Cross-listed with PB-001 (same figure, different cluster); cite once. DF reading (demonized feminine) is distinct from PB reading (corpse-world). [v0.20 source-pass] Useful finding: the text itself stages the shift from protective mother to monster, so 'demonised' need not be imported from outside. Caveat recorded in the counter-reading column. Tiers untouched. | O20: MFM §7 / §8 | P20: Enuma Elis, Tablets I-IV. Same primary as PB-001; different reading. | Q20: Ee I: Tiamat refuses Apsu's plan to destroy their children (the sympathetic phase). Ee II-IV: she becomes the monstrous adversary who appoints Qingu and raises the eleven creatures. The demonisation arc is internal to the text and datable within it - that is the row's strongest evidence. Pin the Tablet I lines. | R20: Lambert, W. G., Babylonian Creation Myths (Eisenbrauns, 2013) = standard critical edition. Dalley, S., Myths from Mesopotamia, rev. ed. (OUP, 2000) = working translation. Talon, SAACT 4. eBL (electronic Babylonian Library) for the composite text and line numbering. | S20: Use MR-01 + MR-03 | U20: Medium until source pass complete | V20: Run model review, then source-pass [v0.20 source-pass] Pin Ee I lines for the refusal-of-Apsu passage. | W20: Lambert 2013, Babylonian Creation Myths, Eisenbrauns | Dalley 2000, Myths from Mesopotamia, OUP: Tablet I at p. 234, Tablet II at pp. 243-244, Tablet VI at p. 261 (pages verified via secondary quotation, not opened in-edition) | X20: 2026-07-29 | Y20: Tier 1 | Z20: Tier 2 | AA20: Supportive | AB20: DF-01's 'requires specialist mediation' element is absent. Tiamat is destroyed, not managed. Contrast DF-002 Lamashtu, where the warding apparatus is the entire point. | AC20: Partial fit | AD20: Same contested reading as PB-001: if Tiamat is primarily a cosmological principle, the gendered-administration frame is imported. The row is strongest on the internal protective-mother -> monster shift, weakest on the mediation claim. | AE20: Legacy — not yet tagged
A21: DF-002 | B21: DF-01 | C21: Demonized Feminine / Unadministrable Woman | E21: Mesopotamian | F21: Lamashtu | G21: Female being linked with infant death, miscarriage, disease, childbirth danger. | H21: Birth-threshold terror personified as dangerous female power. | I21: Fear becomes symbol; ritual system mediates danger. | J21: Childbirth terror and family vulnerability remain underneath demon form. | K21: Lilith; Lamia; Strix; Pazuzu warding pair | L21: Tier 1-2 | M21: Needs source pass | N21: Frame as druj-at-threshold, not Christian demon. [v0.19] Paired case with BW-001 (Pazuzu): birth-threshold warding; function-scan, not good-vs-evil. | O21: MFM §10 | P21: TBD: identify primary text/artifact | Q21: TBD: exact passage, tablet, chapter, hymn, codex plate, or oral-transcription source | R21: TBD: one reputable secondary source | S21: Use MR-01 + MR-03 | U21: Medium until source pass complete | V21: Run model review, then source-pass | Y21: Tier 1 | Z21: Tier 1-2 | AA21: Load-bearing | AC21: Not yet tested | AE21: Legacy — not yet tagged
A22: DF-003 | B22: DF-01 | C22: Demonized Feminine / Unadministrable Woman | E22: Jewish / later medieval drift | F22: Lilith | G22: Night demon / refusal figure in later popular story. | H22: Female sexual/autonomous refusal becomes demon grammar. | I22: Later tradition splits administrable woman from dangerous woman. | J22: Older night/demon material becomes autonomy symbol under pressure. | K22: Lamashtu; Lamia; Eve; witch figures | L22: Tier 1-2 | M22: Anchored; Blair is counter-voice; stays Quarantine | N22: Caveat: refusal-submission story is medieval; older Lilith material differs. [v0.19.1 source-pass] Dated strata: ancient night-demon (Isaiah/Talmud) vs medieval first-wife (Ben Sira, geonic c. 7th-10th c.) vs modern reclamation. Blair 2009 recorded as COUNTER-voice (verified thesis: lilith = night bird, not demon). Stays Quarantine. Tier unchanged. | O22: MFM §8 | P22: Isaiah 34:14 (lilit among Edom's ruins); b. Shabbat 151b; b. Niddah 24b; Alphabet of Ben Sira (medieval) for the equality/refusal scene. | Q22: Isa 34:14; b. Shabbat 151b; b. Niddah 24b; Ben Sira refusal scene - verify in-edition. | R22: Blair, De-Demonising the Old Testament (Mohr Siebeck, 2009) - COUNTER-voice: argues lilith is a night bird, NOT a demon. Do NOT cite as support for the demonized-feminine reading. | S22: Use MR-01 + MR-03 | U22: Medium until source pass complete | V22: Run model review, then source-pass [v0.19] SPLIT strata: (a) ancient lilitu night-demon, (b) medieval Alphabet of Ben Sira refusal-wife, (c) modern reclamation. Modern-overlay risk. [v0.19.1] Quarantine = handling discipline, not weak evidence. | W22: Blair 2009 (Mohr Siebeck), ISBN 9783161501319; thesis: era.ed.ac.uk/handle/1842/3480 | Y22: Tier 2 | Z22: Tier 3 | AA22: Quarantine | AC22: Not yet tested | AE22: Legacy — not yet tagged
A23: DF-004 | B23: DF-01 | C23: Demonized Feminine / Unadministrable Woman | E23: Greek | F23: Medusa | G23: Monster woman killed; head becomes weapon/trophy. | H23: Dangerous female face/body is made killable and then usable by hero/order. | I23: Female terror is captured and weaponized by authorized male heroics. | J23: The head keeps power after death. | K23: Lamashtu; Lilith; Coyolxauhqui; Kali caveat | L23: Tier 2 | M23: Partial; primary loci noted; secondary owed | N23: Many variants; avoid modern-only reduction. [v0.19.1 source-pass] Sympathetic rape/transformation backstory is OVIDIAN (Metamorphoses 4), later reception - do NOT fold into primary. If the row leans on it as primary, possible tier-conflict: FLAGGED, tier NOT changed (K9-K11). Secondary still owed. Support: partial. | O23: Comparative candidate | P23: [Pseudo-]Apollodorus, Bibliotheca; Hesiod, Theogony (Gorgon genealogy). NOT primary: Ovid, Metamorphoses 4 (later reception). | Q23: Apollodorus 2.4.2-3 (Medusa beheaded; head set on Athena's aegis/shield); Hesiod, Theog. (Gorgon lineage). | R23: NOT FOUND - secondary still owed. | S23: Use MR-01 + MR-03 | U23: Medium until source pass complete | V23: Run model review, then source-pass [v0.19] Source-pass: interpretation is version/iconography-dependent (Ovid = late reception); pin the version. | W23: Primary editions to confirm (Apollodorus 2.4.2-3; Hesiod Theogony). Secondary owed. | Y23: Tier 2 | Z23: Tier 3 | AA23: Source-pass | AC23: Not yet tested | AE23: Legacy — not yet tagged
